[2023-07-20 06:36:19,419] {taskinstance.py:1043} INFO - Dependencies all met for <TaskInstance: ingest_data.download_dataset_task scheduled__2023-07-19T00:00:00+00:00 [queued]>
[2023-07-20 06:36:19,433] {taskinstance.py:1043} INFO - Dependencies all met for <TaskInstance: ingest_data.download_dataset_task scheduled__2023-07-19T00:00:00+00:00 [queued]>
[2023-07-20 06:36:19,433] {taskinstance.py:1249} INFO - 
--------------------------------------------------------------------------------
[2023-07-20 06:36:19,434] {taskinstance.py:1250} INFO - Starting attempt 1 of 2
[2023-07-20 06:36:19,434] {taskinstance.py:1251} INFO - 
--------------------------------------------------------------------------------
[2023-07-20 06:36:19,453] {taskinstance.py:1270} INFO - Executing <Task(BashOperator): download_dataset_task> on 2023-07-19 00:00:00+00:00
[2023-07-20 06:36:19,462] {standard_task_runner.py:52} INFO - Started process 118 to run task
[2023-07-20 06:36:19,469] {standard_task_runner.py:79} INFO - Running: ['***', 'tasks', 'run', 'ingest_data', 'download_dataset_task', 'scheduled__2023-07-19T00:00:00+00:00', '--job-id', '774', '--raw', '--subdir', 'DAGS_FOLDER/ingest_data_listing_q4.py', '--cfg-path', '/tmp/tmpmwkxd755', '--error-file', '/tmp/tmpjmvbejyx']
[2023-07-20 06:36:19,470] {standard_task_runner.py:80} INFO - Job 774: Subtask download_dataset_task
[2023-07-20 06:36:19,544] {logging_mixin.py:109} INFO - Running <TaskInstance: ingest_data.download_dataset_task scheduled__2023-07-19T00:00:00+00:00 [running]> on host e6b02974a23b
[2023-07-20 06:36:19,590] {taskinstance.py:1743} WARNING - We expected to get frame set in local storage but it was not. Please report this as an issue with full logs at https://github.com/apache/***/issues/new
Traceback (most recent call last):
  File "/home/airflow/.local/lib/python3.9/site-packages/sqlalchemy/engine/base.py", line 1276, in _execute_context
    self.dialect.do_execute(
  File "/home/airflow/.local/lib/python3.9/site-packages/sqlalchemy/engine/default.py", line 608, in do_execute
    cursor.execute(statement, parameters)
psycopg2.errors.UndefinedColumn: column xcom.execution_date does not exist
LINE 1: ...a' AND xcom.task_id = 'download_dataset_task' AND xcom.execu...
                                                             ^


The above exception was the direct cause of the following exception:

Traceback (most recent call last):
  File "/home/airflow/.local/lib/python3.9/site-packages/airflow/models/taskinstance.py", line 1340, in _run_raw_task
    self._execute_task_with_callbacks(context)
  File "/home/airflow/.local/lib/python3.9/site-packages/airflow/models/taskinstance.py", line 1437, in _execute_task_with_callbacks
    self.clear_xcom_data()
  File "/home/airflow/.local/lib/python3.9/site-packages/airflow/utils/session.py", line 70, in wrapper
    return func(*args, session=session, **kwargs)
  File "/home/airflow/.local/lib/python3.9/site-packages/airflow/models/taskinstance.py", line 799, in clear_xcom_data
    XCom.clear(
  File "/home/airflow/.local/lib/python3.9/site-packages/airflow/utils/session.py", line 67, in wrapper
    return func(*args, **kwargs)
  File "/home/airflow/.local/lib/python3.9/site-packages/airflow/models/xcom.py", line 437, in clear
    return query.delete()
  File "/home/airflow/.local/lib/python3.9/site-packages/sqlalchemy/orm/query.py", line 3926, in delete
    delete_op.exec_()
  File "/home/airflow/.local/lib/python3.9/site-packages/sqlalchemy/orm/persistence.py", line 1697, in exec_
    self._do_exec()
  File "/home/airflow/.local/lib/python3.9/site-packages/sqlalchemy/orm/persistence.py", line 1930, in _do_exec
    self._execute_stmt(delete_stmt)
  File "/home/airflow/.local/lib/python3.9/site-packages/sqlalchemy/orm/persistence.py", line 1702, in _execute_stmt
    self.result = self.query._execute_crud(stmt, self.mapper)
  File "/home/airflow/.local/lib/python3.9/site-packages/sqlalchemy/orm/query.py", line 3568, in _execute_crud
    return conn.execute(stmt, self._params)
  File "/home/airflow/.local/lib/python3.9/site-packages/sqlalchemy/engine/base.py", line 1011, in execute
    return meth(self, multiparams, params)
  File "/home/airflow/.local/lib/python3.9/site-packages/sqlalchemy/sql/elements.py", line 298, in _execute_on_connection
    return connection._execute_clauseelement(self, multiparams, params)
  File "/home/airflow/.local/lib/python3.9/site-packages/sqlalchemy/engine/base.py", line 1124, in _execute_clauseelement
    ret = self._execute_context(
  File "/home/airflow/.local/lib/python3.9/site-packages/sqlalchemy/engine/base.py", line 1316, in _execute_context
    self._handle_dbapi_exception(
  File "/home/airflow/.local/lib/python3.9/site-packages/sqlalchemy/engine/base.py", line 1510, in _handle_dbapi_exception
    util.raise_(
  File "/home/airflow/.local/lib/python3.9/site-packages/sqlalchemy/util/compat.py", line 182, in raise_
    raise exception
  File "/home/airflow/.local/lib/python3.9/site-packages/sqlalchemy/engine/base.py", line 1276, in _execute_context
    self.dialect.do_execute(
  File "/home/airflow/.local/lib/python3.9/site-packages/sqlalchemy/engine/default.py", line 608, in do_execute
    cursor.execute(statement, parameters)
sqlalchemy.exc.ProgrammingError: (psycopg2.errors.UndefinedColumn) column xcom.execution_date does not exist
LINE 1: ...a' AND xcom.task_id = 'download_dataset_task' AND xcom.execu...
                                                             ^

[SQL: DELETE FROM xcom WHERE xcom.dag_id = %(dag_id_1)s AND xcom.task_id = %(task_id_1)s AND xcom.execution_date = %(execution_date_1)s]
[parameters: {'dag_id_1': 'ingest_data', 'task_id_1': 'download_dataset_task', 'execution_date_1': datetime.datetime(2023, 7, 19, 0, 0, tzinfo=Timezone('UTC'))}]
(Background on this error at: http://sqlalche.me/e/13/f405)

During handling of the above exception, another exception occurred:

Traceback (most recent call last):
  File "/home/airflow/.local/lib/python3.9/site-packages/airflow/models/taskinstance.py", line 1741, in get_truncated_error_traceback
    execution_frame = _TASK_EXECUTION_FRAME_LOCAL_STORAGE.frame
AttributeError: '_thread._local' object has no attribute 'frame'
[2023-07-20 06:36:19,598] {taskinstance.py:1774} ERROR - Task failed with exception
Traceback (most recent call last):
  File "/home/airflow/.local/lib/python3.9/site-packages/sqlalchemy/engine/base.py", line 1276, in _execute_context
    self.dialect.do_execute(
  File "/home/airflow/.local/lib/python3.9/site-packages/sqlalchemy/engine/default.py", line 608, in do_execute
    cursor.execute(statement, parameters)
psycopg2.errors.UndefinedColumn: column xcom.execution_date does not exist
LINE 1: ...a' AND xcom.task_id = 'download_dataset_task' AND xcom.execu...
                                                             ^


The above exception was the direct cause of the following exception:

Traceback (most recent call last):
  File "/home/airflow/.local/lib/python3.9/site-packages/airflow/models/taskinstance.py", line 1340, in _run_raw_task
    self._execute_task_with_callbacks(context)
  File "/home/airflow/.local/lib/python3.9/site-packages/airflow/models/taskinstance.py", line 1437, in _execute_task_with_callbacks
    self.clear_xcom_data()
  File "/home/airflow/.local/lib/python3.9/site-packages/airflow/utils/session.py", line 70, in wrapper
    return func(*args, session=session, **kwargs)
  File "/home/airflow/.local/lib/python3.9/site-packages/airflow/models/taskinstance.py", line 799, in clear_xcom_data
    XCom.clear(
  File "/home/airflow/.local/lib/python3.9/site-packages/airflow/utils/session.py", line 67, in wrapper
    return func(*args, **kwargs)
  File "/home/airflow/.local/lib/python3.9/site-packages/airflow/models/xcom.py", line 437, in clear
    return query.delete()
  File "/home/airflow/.local/lib/python3.9/site-packages/sqlalchemy/orm/query.py", line 3926, in delete
    delete_op.exec_()
  File "/home/airflow/.local/lib/python3.9/site-packages/sqlalchemy/orm/persistence.py", line 1697, in exec_
    self._do_exec()
  File "/home/airflow/.local/lib/python3.9/site-packages/sqlalchemy/orm/persistence.py", line 1930, in _do_exec
    self._execute_stmt(delete_stmt)
  File "/home/airflow/.local/lib/python3.9/site-packages/sqlalchemy/orm/persistence.py", line 1702, in _execute_stmt
    self.result = self.query._execute_crud(stmt, self.mapper)
  File "/home/airflow/.local/lib/python3.9/site-packages/sqlalchemy/orm/query.py", line 3568, in _execute_crud
    return conn.execute(stmt, self._params)
  File "/home/airflow/.local/lib/python3.9/site-packages/sqlalchemy/engine/base.py", line 1011, in execute
    return meth(self, multiparams, params)
  File "/home/airflow/.local/lib/python3.9/site-packages/sqlalchemy/sql/elements.py", line 298, in _execute_on_connection
    return connection._execute_clauseelement(self, multiparams, params)
  File "/home/airflow/.local/lib/python3.9/site-packages/sqlalchemy/engine/base.py", line 1124, in _execute_clauseelement
    ret = self._execute_context(
  File "/home/airflow/.local/lib/python3.9/site-packages/sqlalchemy/engine/base.py", line 1316, in _execute_context
    self._handle_dbapi_exception(
  File "/home/airflow/.local/lib/python3.9/site-packages/sqlalchemy/engine/base.py", line 1510, in _handle_dbapi_exception
    util.raise_(
  File "/home/airflow/.local/lib/python3.9/site-packages/sqlalchemy/util/compat.py", line 182, in raise_
    raise exception
  File "/home/airflow/.local/lib/python3.9/site-packages/sqlalchemy/engine/base.py", line 1276, in _execute_context
    self.dialect.do_execute(
  File "/home/airflow/.local/lib/python3.9/site-packages/sqlalchemy/engine/default.py", line 608, in do_execute
    cursor.execute(statement, parameters)
sqlalchemy.exc.ProgrammingError: (psycopg2.errors.UndefinedColumn) column xcom.execution_date does not exist
LINE 1: ...a' AND xcom.task_id = 'download_dataset_task' AND xcom.execu...
                                                             ^

[SQL: DELETE FROM xcom WHERE xcom.dag_id = %(dag_id_1)s AND xcom.task_id = %(task_id_1)s AND xcom.execution_date = %(execution_date_1)s]
[parameters: {'dag_id_1': 'ingest_data', 'task_id_1': 'download_dataset_task', 'execution_date_1': datetime.datetime(2023, 7, 19, 0, 0, tzinfo=Timezone('UTC'))}]
(Background on this error at: http://sqlalche.me/e/13/f405)
[2023-07-20 06:36:19,612] {taskinstance.py:1278} INFO - Marking task as UP_FOR_RETRY. dag_id=ingest_data, task_id=download_dataset_task, execution_date=20230719T000000, start_date=20230720T063619, end_date=20230720T063619
[2023-07-20 06:36:19,627] {standard_task_runner.py:93} ERROR - Failed to execute job 774 for task download_dataset_task ((psycopg2.errors.UndefinedColumn) column "execution_date" of relation "task_fail" does not exist
LINE 1: INSERT INTO task_fail (task_id, dag_id, execution_date, star...
                                                ^

[SQL: INSERT INTO task_fail (task_id, dag_id, execution_date, start_date, end_date, duration) VALUES (%(task_id)s, %(dag_id)s, %(execution_date)s, %(start_date)s, %(end_date)s, %(duration)s) RETURNING task_fail.id]
[parameters: {'task_id': 'download_dataset_task', 'dag_id': 'ingest_data', 'execution_date': datetime.datetime(2023, 7, 19, 0, 0, tzinfo=Timezone('UTC')), 'start_date': datetime.datetime(2023, 7, 20, 6, 36, 19, 420615, tzinfo=Timezone('UTC')), 'end_date': datetime.datetime(2023, 7, 20, 6, 36, 19, 612250, tzinfo=Timezone('UTC')), 'duration': 0}]
(Background on this error at: http://sqlalche.me/e/13/f405); 118)
[2023-07-20 06:36:19,641] {local_task_job.py:154} INFO - Task exited with return code 1
[2023-07-20 06:36:19,672] {taskinstance.py:1278} INFO - Marking task as UP_FOR_RETRY. dag_id=ingest_data, task_id=download_dataset_task, execution_date=20230719T000000, start_date=20230720T063619, end_date=20230720T063619
